[03/12/2023 10:54:42 PM:pyrogram.dispatcher:253:ERROR] Telegram says: [400 QUERY_ID_INVALID] - The callback query id is invalid (caused by "messages.SetBotCallbackAnswer")
Traceback (most recent call last):
  File "C:\Users\91949\EVABOT5\Advance-EvaMaria\plugins\pm_filter.py", line 378, in cb_handler
    await query.answer(url=f"https://t.me/{temp.U_NAME}?start={ident}_{file_id}")
  File "C:\Users\91949\AppData\Local\Packages\PythonSoftwareFoundation.Python.3.10_qbz5n2kfra8p0\LocalCache\local-packages\Python310\site-packages\pyrogram\types\bots_and_keyboards\callback_query.py", line 159, in answer
    return await self._client.answer_callback_query(
  File "C:\Users\91949\AppData\Local\Packages\PythonSoftwareFoundation.Python.3.10_qbz5n2kfra8p0\LocalCache\local-packages\Python310\site-packages\pyrogram\methods\bots\answer_callback_query.py", line 73, in answer_callback_query
    return await self.invoke(
  File "C:\Users\91949\AppData\Local\Packages\PythonSoftwareFoundation.Python.3.10_qbz5n2kfra8p0\LocalCache\local-packages\Python310\site-packages\pyrogram\methods\advanced\invoke.py", line 79, in invoke
    r = await self.session.invoke(
  File "C:\Users\91949\AppData\Local\Packages\PythonSoftwareFoundation.Python.3.10_qbz5n2kfra8p0\LocalCache\local-packages\Python310\site-packages\pyrogram\session\session.py", line 389, in invoke
    return await self.send(query, timeout=timeout)
  File "C:\Users\91949\AppData\Local\Packages\PythonSoftwareFoundation.Python.3.10_qbz5n2kfra8p0\LocalCache\local-packages\Python310\site-packages\pyrogram\session\session.py", line 357, in send
    RPCError.raise_it(result, type(data))
  File "C:\Users\91949\AppData\Local\Packages\PythonSoftwareFoundation.Python.3.10_qbz5n2kfra8p0\LocalCache\local-packages\Python310\site-packages\pyrogram\errors\rpc_error.py", line 91, in raise_it
    raise getattr(
pyrogram.errors.exceptions.bad_request_400.QueryIdInvalid: Telegram says: [400 QUERY_ID_INVALID] - The callback query id is invalid (caused by "messages.SetBotCallbackAnswer")

During handling of the above exception, another exception occurred:

Traceback (most recent call last):
  File "C:\Users\91949\AppData\Local\Packages\PythonSoftwareFoundation.Python.3.10_qbz5n2kfra8p0\LocalCache\local-packages\Python310\site-packages\pyrogram\dispatcher.py", line 240, in handler_worker
    await handler.callback(self.client, *args)
  File "C:\Users\91949\EVABOT5\Advance-EvaMaria\plugins\pm_filter.py", line 393, in cb_handler
    await query.answer(url=f"https://t.me/{temp.U_NAME}?start={ident}_{file_id}")
  File "C:\Users\91949\AppData\Local\Packages\PythonSoftwareFoundation.Python.3.10_qbz5n2kfra8p0\LocalCache\local-packages\Python310\site-packages\pyrogram\types\bots_and_keyboards\callback_query.py", line 159, in answer
    return await self._client.answer_callback_query(
  File "C:\Users\91949\AppData\Local\Packages\PythonSoftwareFoundation.Python.3.10_qbz5n2kfra8p0\LocalCache\local-packages\Python310\site-packages\pyrogram\methods\bots\answer_callback_query.py", line 73, in answer_callback_query
    return await self.invoke(
  File "C:\Users\91949\AppData\Local\Packages\PythonSoftwareFoundation.Python.3.10_qbz5n2kfra8p0\LocalCache\local-packages\Python310\site-packages\pyrogram\methods\advanced\invoke.py", line 79, in invoke
    r = await self.session.invoke(
  File "C:\Users\91949\AppData\Local\Packages\PythonSoftwareFoundation.Python.3.10_qbz5n2kfra8p0\LocalCache\local-packages\Python310\site-packages\pyrogram\session\session.py", line 389, in invoke
    return await self.send(query, timeout=timeout)
  File "C:\Users\91949\AppData\Local\Packages\PythonSoftwareFoundation.Python.3.10_qbz5n2kfra8p0\LocalCache\local-packages\Python310\site-packages\pyrogram\session\session.py", line 357, in send
    RPCError.raise_it(result, type(data))
  File "C:\Users\91949\AppData\Local\Packages\PythonSoftwareFoundation.Python.3.10_qbz5n2kfra8p0\LocalCache\local-packages\Python310\site-packages\pyrogram\errors\rpc_error.py", line 91, in raise_it
    raise getattr(
pyrogram.errors.exceptions.bad_request_400.QueryIdInvalid: Telegram says: [400 QUERY_ID_INVALID] - The callback query id is invalid (caused by "messages.SetBotCallbackAnswer")
